Workbook

Sheet Claims
A1: # | B1: Game | C1: Claim (as written, shortened) | D1: Claim type | E1: Verdict | F1: Error type | G1: Note
A2: 1 | B2: 1 | C2: Mayo 2-14 Galway 2-8 | D2: final score | E2: ok
A3: 2 | B3: 1 | C3: Mayo won / claimed the Connacht title | D3: winner | E3: ok
A4: 3 | B4: 1 | C4: six-point victory | D4: margin | E4: ok
A5: 4 | B5: 1 | C5: Sunday, July 25 | D5: date | E5: ok | G5: weekday is not in the input; computed and correct
A6: 5 | B6: 1 | C6: O'Donoghue and Ruane contributed 2-5 between them | D6: scorer total | E6: ok
A7: 6 | B7: 1 | C7: O'Donoghue 1-3, including a penalty and two pointed frees | D7: scorer detail | E7: ok
A8: 7 | B8: 1 | C8: Ruane 1-2 | D8: scorer total | E8: ok
A9: 8 | B9: 1 | C9: 10 Mayo players on the scoresheet (repeated as "Mayo's 10") | D9: count | E9: error | F9: wrong count | G9: the data lists 9 Mayo scorers
A10: 9 | B10: 1 | C10: Loftus and Conroy two points each | D10: scorer total | E10: ok
A11: 10 | B11: 1 | C11: Hennelly converted a '45 | D11: scorer detail | E11: ok
A12: 11 | B12: 1 | C12: Hennelly is the goalkeeper | D12: added info | E12: not in data (true) | G12: position not in the input
A13: 12 | B13: 1 | C13: Durcan, McHale, McLoughlin, Carr one point each | D13: scorer total | E13: ok
A14: 13 | B14: 1 | C14: both teams scored two goals | D14: final score | E14: ok
A15: 14 | B15: 1 | C15: 14 to 8 in points accounted for the whole margin | D15: derived | E15: ok
A16: 15 | B16: 1 | C16: Galway's leading scorer was Tierney, four points | D16: ranking | E16: partly | F16: ranking | G16: Walsh 1-1 is also 4 points (tie)
A17: 16 | B17: 1 | C17: Tierney: three of his four from frees | D17: scorer detail | E17: ok
A18: 17 | B18: 1 | C18: Walsh 1-1 and Comer a goal | D18: scorer total | E18: ok
A19: 18 | B19: 1 | C19: Paul Conroy two, Sweeney one | D19: scorer total | E19: ok
A20: 19 | B20: 1 | C20: Galway had five scorers | D20: count | E20: ok
A21: 20 | B21: 2 | C21: Laois 2-17 Wexford 2-13 | D21: final score | E21: ok
A22: 21 | B22: 2 | C22: Laois won, four-point victory | D22: margin | E22: ok
A23: 22 | B23: 2 | C23: Sunday, April 9 | D23: date | E23: ok | G23: weekday is not in the input; computed and correct
A24: 23 | B24: 2 | C24: Barry 2-4, two goals | D24: scorer total | E24: ok
A25: 24 | B25: 2 | C25: O'Carroll six points | D25: scorer total | E25: ok
A26: 25 | B26: 2 | C26: Laois total of 23 points | D26: derived | E26: ok
A27: 26 | B27: 2 | C27: Wexford matched Laois on goals | D27: final score | E27: ok
A28: 27 | B28: 2 | C28: Brosnan 1-7 | D28: scorer total | E28: ok
A29: 28 | B29: 2 | C29: Barry and Brosnan ten points each | D29: derived | E29: ok
A30: 29 | B30: 2 | C30: Barry's four points: two frees and a mark | D30: scorer detail | E30: ok
A31: 30 | B31: 2 | C31: O'Carroll: a free, a mark and a 45 among six | D31: scorer detail | E31: ok
A32: 31 | B32: 2 | C32: Kingston four, three from frees | D32: scorer detail | E32: ok
A33: 32 | B33: 2 | C33: Larkin two, O'Sullivan one | D33: scorer total | E33: ok
A34: 33 | B34: 2 | C34: Brosnan: penalty and five frees among seven points | D34: scorer detail | E34: ok
A35: 34 | B35: 2 | C35: Brooks the other goal plus a point | D35: scorer total | E35: ok
... A37: 36 | B37: 2 | C37: Barry, O'Carroll and Kingston all but three of 23 points | D37: derived | E37: ok
A38: 37 | B38: 2 | C38: "opening championship assignment" (preliminary round) | D38: stage | E38: not in data (true) | G38: not stated in the input; plausible
A39: 38 | B39: 3 | C39: Armagh 0-20 Antrim 1-8 | D39: final score | E39: ok
A40: 39 | B40: 3 | C40: Armagh won by nine points | D40: margin | E40: ok
A41: 40 | B41: 3 | C41: Saturday, April 8 | D41: date | E41: ok | G41: weekday is not in the input; computed and correct
...

Sheet Summary
A1: Claim type | B1: Claims | C1: ok | D1: error | E1: partly | F1: not in data (true) | G1: not in data (unverified)
A2: added info | B2: =COUNTIF(Claims!$D$2:$D$147,A2) | C2: =COUNTIFS(Claims!$D$2:$D$147,$A2,Claims!$E$2:$E$147,"ok") | D2: =COUNTIFS(Claims!$D$2:$D$147,$A2,Claims!$E$2:$E$147,"error") | E2: =COUNTIFS(Claims!$D$2:$D$147,$A2,Claims!$E$2:$E$147,"partly") | F2: =COUNTIFS(Claims!$D$2:$D$147,$A2,Claims!$E$2:$E$147,"not in data (true)") | G2: =COUNTIFS(Claims!$D$2:$D$147,$A2,Claims!$E$2:$E$147,"not in data (unverified)")
A3: count | B3: =COUNTIF(Claims!$D$2:$D$147,A3) | C3: =COUNTIFS(Claims!$D$2:$D$147,$A3,Claims!$E$2:$E$147,"ok") | D3: =COUNTIFS(Claims!$D$2:$D$147,$A3,Claims!$E$2:$E$147,"error") | E3: =COUNTIFS(Claims!$D$2:$D$147,$A3,Claims!$E$2:$E$147,"partly") | F3: =COUNTIFS(Claims!$D$2:$D$147,$A3,Claims!$E$2:$E$147,"not in data (true)") | G3: =COUNTIFS(Claims!$D$2:$D$147,$A3,Claims!$E$2:$E$147,"not in data (unverified)")
A4: date | B4: =COUNTIF(Claims!$D$2:$D$147,A4) | C4: =COUNTIFS(Claims!$D$2:$D$147,$A4,Claims!$E$2:$E$147,"ok") | D4: =COUNTIFS(Claims!$D$2:$D$147,$A4,Claims!$E$2:$E$147,"error") | E4: =COUNTIFS(Claims!$D$2:$D$147,$A4,Claims!$E$2:$E$147,"partly") | F4: =COUNTIFS(Claims!$D$2:$D$147,$A4,Claims!$E$2:$E$147,"not in data (true)") | G4: =COUNTIFS(Claims!$D$2:$D$147,$A4,Claims!$E$2:$E$147,"not in data (unverified)")
A5: derived | B5: =COUNTIF(Claims!$D$2:$D$147,A5) | C5: =COUNTIFS(Claims!$D$2:$D$147,$A5,Claims!$E$2:$E$147,"ok") | D5: =COUNTIFS(Claims!$D$2:$D$147,$A5,Claims!$E$2:$E$147,"error") | E5: =COUNTIFS(Claims!$D$2:$D$147,$A5,Claims!$E$2:$E$147,"partly") | F5: =COUNTIFS(Claims!$D$2:$D$147,$A5,Claims!$E$2:$E$147,"not in data (true)") | G5: =COUNTIFS(Claims!$D$2:$D$147,$A5,Claims!$E$2:$E$147,"not in data (unverified)")
A6: final score | B6: =COUNTIF(Claims!$D$2:$D$147,A6) | C6: =COUNTIFS(Claims!$D$2:$D$147,$A6,Claims!$E$2:$E$147,"ok") | D6: =COUNTIFS(Claims!$D$2:$D$147,$A6,Claims!$E$2:$E$147,"error") | E6: =COUNTIFS(Claims!$D$2:$D$147,$A6,Claims!$E$2:$E$147,"partly") | F6: =COUNTIFS(Claims!$D$2:$D$147,$A6,Claims!$E$2:$E$147,"not in data (true)") | G6: =COUNTIFS(Claims!$D$2:$D$147,$A6,Claims!$E$2:$E$147,"not in data (unverified)")
A7: invented entity | B7: =COUNTIF(Claims!$D$2:$D$147,A7) | C7: =COUNTIFS(Claims!$D$2:$D$147,$A7,Claims!$E$2:$E$147,"ok") | D7: =COUNTIFS(Claims!$D$2:$D$147,$A7,Claims!$E$2:$E$147,"error") | E7: =COUNTIFS(Claims!$D$2:$D$147,$A7,Claims!$E$2:$E$147,"partly") | F7: =COUNTIFS(Claims!$D$2:$D$147,$A7,Claims!$E$2:$E$147,"not in data (true)") | G7: =COUNTIFS(Claims!$D$2:$D$147,$A7,Claims!$E$2:$E$147,"not in data (unverified)")
A8: margin | B8: =COUNTIF(Claims!$D$2:$D$147,A8) | C8: =COUNTIFS(Claims!$D$2:$D$147,$A8,Claims!$E$2:$E$147,"ok") | D8: =COUNTIFS(Claims!$D$2:$D$147,$A8,Claims!$E$2:$E$147,"error") | E8: =COUNTIFS(Claims!$D$2:$D$147,$A8,Claims!$E$2:$E$147,"partly") | F8: =COUNTIFS(Claims!$D$2:$D$147,$A8,Claims!$E$2:$E$147,"not in data (true)") | G8: =COUNTIFS(Claims!$D$2:$D$147,$A8,Claims!$E$2:$E$147,"not in data (unverified)")
A9: ranking | B9: =COUNTIF(Claims!$D$2:$D$147,A9) | C9: =COUNTIFS(Claims!$D$2:$D$147,$A9,Claims!$E$2:$E$147,"ok") | D9: =COUNTIFS(Claims!$D$2:$D$147,$A9,Claims!$E$2:$E$147,"error") | E9: =COUNTIFS(Claims!$D$2:$D$147,$A9,Claims!$E$2:$E$147,"partly") | F9: =COUNTIFS(Claims!$D$2:$D$147,$A9,Claims!$E$2:$E$147,"not in data (true)") | G9: =COUNTIFS(Claims!$D$2:$D$147,$A9,Claims!$E$2:$E$147,"not in data (unverified)")
A10: scorer detail | B10: =COUNTIF(Claims!$D$2:$D$147,A10) | C10: =COUNTIFS(Claims!$D$2:$D$147,$A10,Claims!$E$2:$E$147,"ok") | D10: =COUNTIFS(Claims!$D$2:$D$147,$A10,Claims!$E$2:$E$147,"error") | E10: =COUNTIFS(Claims!$D$2:$D$147,$A10,Claims!$E$2:$E$147,"partly") | F10: =COUNTIFS(Claims!$D$2:$D$147,$A10,Claims!$E$2:$E$147,"not in data (true)") | G10: =COUNTIFS(Claims!$D$2:$D$147,$A10,Claims!$E$2:$E$147,"not in data (unverified)")
A11: scorer total | B11: =COUNTIF(Claims!$D$2:$D$147,A11) | C11: =COUNTIFS(Claims!$D$2:$D$147,$A11,Claims!$E$2:$E$147,"ok") | D11: =COUNTIFS(Claims!$D$2:$D$147,$A11,Claims!$E$2:$E$147,"error") | E11: =COUNTIFS(Claims!$D$2:$D$147,$A11,Claims!$E$2:$E$147,"partly") | F11: =COUNTIFS(Claims!$D$2:$D$147,$A11,Claims!$E$2:$E$147,"not in data (true)") | G11: =COUNTIFS(Claims!$D$2:$D$147,$A11,Claims!$E$2:$E$147,"not in data (unverified)")
A12: stage | B12: =COUNTIF(Claims!$D$2:$D$147,A12) | C12: =COUNTIFS(Claims!$D$2:$D$147,$A12,Claims!$E$2:$E$147,"ok") | D12: =COUNTIFS(Claims!$D$2:$D$147,$A12,Claims!$E$2:$E$147,"error") | E12: =COUNTIFS(Claims!$D$2:$D$147,$A12,Claims!$E$2:$E$147,"partly") | F12: =COUNTIFS(Claims!$D$2:$D$147,$A12,Claims!$E$2:$E$147,"not in data (true)") | G12: =COUNTIFS(Claims!$D$2:$D$147,$A12,Claims!$E$2:$E$147,"not in data (unverified)")
A13: winner | B13: =COUNTIF(Claims!$D$2:$D$147,A13) | C13: =COUNTIFS(Claims!$D$2:$D$147,$A13,Claims!$E$2:$E$147,"ok") | D13: =COUNTIFS(Claims!$D$2:$D$147,$A13,Claims!$E$2:$E$147,"error") | E13: =COUNTIFS(Claims!$D$2:$D$147,$A13,Claims!$E$2:$E$147,"partly") | F13: =COUNTIFS(Claims!$D$2:$D$147,$A13,Claims!$E$2:$E$147,"not in data (true)") | G13: =COUNTIFS(Claims!$D$2:$D$147,$A13,Claims!$E$2:$E$147,"not in data (unverified)")
A14: Total | B14: =SUM(B2:B13) | C14: =SUM(C2:C13) | D14: =SUM(D2:D13) | E14: =SUM(E2:E13) | F14: =SUM(F2:F13) | G14: =SUM(G2:G13)

Sheet Notes
A1: Pilot run 2026-10-28_2207, prompt v1 (condition A), model gpt-6.1-sol. Games 1-9 only: game 10 (Armagh v Kerry) went to extra time and is out of scope.
A2: Each claim was checked by hand against code/data/processed/pilot_inputs.json (scorers, score and the truth block).
A3: Verdicts: ok = supported by the input or follows from it; error = contradicts the input or invents something; partly = literally true but misleading; not in data = not in the input, so it comes from the model (true / unverified).
A4: "From play" claims are counted as ok when the input has no note on the points (the notation only marks frees, marks, 45s and penalties).
A5: The weekday of each date is not in the input; all nine were computed and match.
A6: The list is a hand selection of the factual claims of each report, not an automatic extraction. Interpretive phrases ("convincing", "deserved") are not claims.
A7: One reader only. A second pass over the "ok" rows would reduce the chance of a missed error.
